Workbook

Sheet 🕵️ לוח בקרה
A1: 🕵️ מבצע XLOOKUP — תיק 404: ההזמנה שנעלמה
A2: הזמנה מספר 404 נעלמה ממערכת ההזמנות. הלקוח מתקשר, המנהלת לוחצת, ואף אחד לא מצליח לשחזר מה בדיוק הוזמן, על ידי מי, ולאן זה היה אמור להגיע.
A3: כל המידע עדיין קיים — אבל הוא מפוזר על פני חמש טבלאות נפרדות. וזה, במקרה, בדיוק מה שאתן יודעות לעשות.
A4: כל תשובה נכונה חושפת ספרה אחת מקוד בן שש ספרות. שש ספרות — והתיק נפתח.
A6: התחנה | B6: סוג החיפוש | C6: סטטוס | D6: ניקוד | E6: הספרה שנחשפה
A7: 1️⃣ מי הלקוח שביצע את ההזמנה | B7: מדויק | C7: =IF('תחנה 1'!B6="","⬜ טרם",IF('תחנה 1'!B6=3187,"✔ הושלם","✖ בדקו שוב")) | D7: =IF(AND(NOT('תחנה 1'!B6=""),'תחנה 1'!B6=3187),15,0) | E7: =IF(AND(NOT('תחנה 1'!B6=""),'תחנה 1'!B6=3187),"4","🔒")
A8: 2️⃣ מה הוזמן, ומה המחיר | B8: מדויק | C8: =IF('תחנה 2'!B6="","⬜ טרם",IF('תחנה 2'!B6=52,"✔ הושלם","✖ בדקו שוב")) | D8: =IF(AND(NOT('תחנה 2'!B6=""),'תחנה 2'!B6=52),15,0) | E8: =IF(AND(NOT('תחנה 2'!B6=""),'תחנה 2'!B6=52),"0","🔒")
A9: 3️⃣ השם שמאחורי המספר | B9: מדויק — טבלה הפוכה | C9: =IF('תחנה 3'!B6="","⬜ טרם",IF(TRIM('תחנה 3'!B6)="רותם אביב","✔ הושלם","✖ בדקו שוב")) | D9: =IF(AND(NOT('תחנה 3'!B6=""),TRIM('תחנה 3'!B6)="רותם אביב"),15,0) | E9: =IF(AND(NOT('תחנה 3'!B6=""),TRIM('תחנה 3'!B6)="רותם אביב"),"2","🔒")
A10: 4️⃣ דמי משלוח לפי משקל | B10: לא מדויק | C10: =IF('תחנה 4'!B6="","⬜ טרם",IF('תחנה 4'!B6=39,"✔ הושלם","✖ בדקו שוב")) | D10: =IF(AND(NOT('תחנה 4'!B6=""),'תחנה 4'!B6=39),15,0) | E10: =IF(AND(NOT('תחנה 4'!B6=""),'תחנה 4'!B6=39),"9","🔒")
A11: 5️⃣ אזור החלוקה לפי מיקוד | B11: לא מדויק | C11: =IF('תחנה 5'!B6="","⬜ טרם",IF('תחנה 5'!B6=33,"✔ הושלם","✖ בדקו שוב")) | D11: =IF(AND(NOT('תחנה 5'!B6=""),'תחנה 5'!B6=33),15,0) | E11: =IF(AND(NOT('תחנה 5'!B6=""),'תחנה 5'!B6=33),"1","🔒")
A12: 6️⃣ הסכום הסופי | B12: הצלבה | C12: =IF('תחנה 6'!B6="","⬜ טרם",IF('תחנה 6'!B6=351,"✔ הושלם","✖ בדקו שוב")) | D12: =IF(AND(NOT('תחנה 6'!B6=""),'תחנה 6'!B6=351),25,0) | E12: =IF(AND(NOT('תחנה 6'!B6=""),'תחנה 6'!B6=351),"7","🔒")
A13: סה"כ ניקוד (מתוך 100) | D13: =SUM(D7:D12)
A15: 🔐 הקוד שנחשף עד כה
A16: =IF(COUNTIF(E7:E12,"🔒")>0,IF(COUNTIF(E7:E12,"🔒")=1,"עדיין נעול — ספרה אחת חסרה","עדיין נעול — " & COUNTIF(E7:E12,"🔒") & " ספרות חסרות"),E7&E8&E9&E10&E11&E12)
A18: 🔑 כחול = נתון קבוע, אל תיגעו. צהוב = כאן ואך ורק כאן כותבים. ירוק = מתעדכן לבד.
A19: 💡 נתקעתן? יש גיליון "עזרה" עם רמז עדין לכל תחנה. להשתמש בו זה לא לרמות — זה חלק מהמשחק.
A20: ⚠️ תחנה 6 מסתמכת על תחנות 2 ו-4. אם היא לא מסתדרת — חזרו אחורה ובדקו אותן.

Sheet 📁 נתוני המערכת
A1: 📁 נתוני המערכת — כל הראיות במקום אחד
A2: חמש טבלאות. שימו לב לסדר העמודות בכל אחת — הוא לא תמיד מה שהייתן מצפות.
A4: טבלה א׳ — הזמנות
A5: מספר הזמנה | B5: מספר לקוח | C5: מק"ט | D5: כמות
A6: 401 | B6: 2044 | C6: K-118 | D6: 3
A7: 402 | B7: 3187 | C7: K-305 | D7: 1
A8: 403 | B8: 5521 | C8: K-220 | D8: 12
A9: 404 | B9: 3187 | C9: K-220 | D9: 6
A10: 405 | B10: 1290 | C10: K-410 | D10: 2
A11: 406 | B11: 4763 | C11: K-118 | D11: 8
A12: 407 | B12: 2044 | C12: K-512 | D12: 5
A13: 408 | B13: 5521 | C13: K-305 | D13: 4
A14: 409 | B14: 6108 | C14: K-220 | D14: 1
A15: 410 | B15: 1290 | C15: K-410 | D15: 9
A16: 411 | B16: 4763 | C16: K-512 | D16: 2
A17: 412 | B17: 6108 | C17: K-118 | D17: 7
A19: טבלה ב׳ — לקוחות
A20: שם לקוח | B20: מספר לקוח | C20: מיקוד | D20: עיר
A21: דנה אלמוג | B21: 1290 | C21: 6407 | D21: תל אביב
A22: יואב נחום | B22: 2044 | C22: 3109 | D22: חיפה
A23: רותם אביב | B23: 3187 | C23: 4520 | D23: רעננה
A24: שירה בן-דוד | B24: 4763 | C24: 8410 | D24: באר שבע
A25: אלון כרמי | B25: 5521 | C25: 1220 | D25: צפת
A26: מאיה שלו | B26: 6108 | C26: 6120 | D26: תל אביב
A28: טבלה ג׳ — מוצרים
A29: מק"ט | B29: שם מוצר | C29: מחיר ליחידה | D29: משקל ליחידה (ק"ג)
A30: K-118 | B30: מקלדת אלחוטית | C30: 120 | D30: 0.8
A31: K-220 | B31: רמקול שולחני | C31: 52 | D31: 3
A32: K-305 | B32: עכבר ארגונומי | C32: 89 | D32: 0.4
A33: K-410 | B33: מצלמת רשת | C33: 210 | D33: 0.5
A34: K-512 | B34: מעמד למחשב נייד | C34: 145 | D34: 1.2
A36: טבלה ד׳ — מדרגות דמי משלוח
A37: משקל מ- (ק"ג) | B37: דמי משלוח
A38: 0 | B38: 15
A39: 5 | B39: 25
A40: 10 | B40: 39
A41: 25 | B41: 60
A42: 50 | B42: 95
A44: טבלה ה׳ — אזורי חלוקה לפי מיקוד
A45: מיקוד מ- | B45: אזור | C45: קוד אזור
...

Sheet תחנה 1
A1: 1️⃣ תחנה 1 — מי הלקוח שביצע את ההזמנה
A2: הדבר הראשון שרוצים לדעת על הזמנה 404: מי בכלל הזמין אותה.
A3: עברו לגיליון "נתוני המערכת", טבלה א׳ (הזמנות), וחפשו את הזמנה 404. מה מספר הלקוח שרשום לידה?
A4: כתבו נוסחת XLOOKUP בתא הצהוב — לא להעתיק בעיניים. זו כל הנקודה.
A6: מספר הלקוח של הזמנה 404: | C6: =IF(B6="","⬜ ממתין לתשובה",IF(B6=3187,"✔ נכון — ספרה נחשפה!","✖ לא מדויק, נסו שוב"))
A8: 💡 נתקעתן? גיליון "עזרה" ← תחנה 1
A9: ↩️ חזרה ל"לוח בקרה" כדי לראות אילו ספרות כבר נחשפו.

Sheet תחנה 2
A1: 2️⃣ תחנה 2 — מה הוזמן, ומה המחיר
A2: עכשיו נגלה מה הלקוח בכלל הזמין. בטבלה א׳ רשום מק"ט לכל הזמנה, ובטבלה ג׳ (מוצרים) רשום מה כל מק"ט אומר.
A3: זה דורש שני חיפושים בשרשרת: קודם המק"ט של הזמנה 404, ואז המחיר של אותו מק"ט.
A4: אפשר לעשות את זה בשני שלבים (בשני תאים), או בנוסחה אחת מקוננת — שתיהן תשובות נכונות.
A6: המחיר ליחידה של המוצר שהוזמן (₪): | C6: =IF(B6="","⬜ ממתין לתשובה",IF(B6=52,"✔ נכון — ספרה נחשפה!","✖ לא מדויק, נסו שוב"))
A8: 💡 נתקעתן? גיליון "עזרה" ← תחנה 2
A9: ↩️ חזרה ל"לוח בקרה" כדי לראות אילו ספרות כבר נחשפו.

Sheet תחנה 3
A1: 3️⃣ תחנה 3 — השם שמאחורי המספר
A2: יש לנו מספר לקוח (מתחנה 1), ואנחנו רוצים שם.
A3: ⚠️ שימו לב לטבלה ב׳ (לקוחות): עמודת השם נמצאת *לפני* עמודת מספר הלקוח. ב-VLOOKUP זה היה בלתי אפשרי בלי טריקים.
A4: ב-XLOOKUP לא צריך לעשות שום דבר מיוחד — רק לסמן את עמודת החיפוש ואת עמודת התשובה, בסדר הנכון.
A6: שם הלקוח של הזמנה 404: | C6: =IF(B6="","⬜ ממתין לתשובה",IF(TRIM(B6)="רותם אביב","✔ נכון — ספרה נחשפה!","✖ לא מדויק, נסו שוב"))
A8: 💡 נתקעתן? גיליון "עזרה" ← תחנה 3
A9: ↩️ חזרה ל"לוח בקרה" כדי לראות אילו ספרות כבר נחשפו.

Sheet תחנה 4
A1: 4️⃣ תחנה 4 — דמי משלוח לפי משקל
A2: כדי לשחזר את ההזמנה צריך גם את דמי המשלוח. הם נקבעים לפי המשקל הכולל של החבילה.
A3: המשקל הכולל = הכמות שהוזמנה × משקל היחידה של המוצר (שתיהן בנתוני המערכת).
A4: ⚠️ המשקל שיצא לכן כמעט בוודאות לא מופיע בטבלת המדרגות — ובכוונה. זו בדיוק המדרגה שמתחת.
A6: דמי המשלוח של הזמנה 404 (₪): | C6: =IF(B6="","⬜ ממתין לתשובה",IF(B6=39,"✔ נכון — ספרה נחשפה!","✖ לא מדויק, נסו שוב"))
A8: 💡 נתקעתן? גיליון "עזרה" ← תחנה 4
A9: ↩️ חזרה ל"לוח בקרה" כדי לראות אילו ספרות כבר נחשפו.

Sheet תחנה 5
A1: 5️⃣ תחנה 5 — אזור החלוקה
A2: לאן החבילה הייתה אמורה להגיע? לכל לקוח יש מיקוד (טבלה ב׳), ולכל טווח מיקודים יש קוד אזור (טבלה ה׳).
A3: קחו את המיקוד של הלקוח שמצאתן, ומצאו את קוד האזור שלו.
A4: ⚠️ גם כאן: המיקוד המדויק לא מופיע בטבלת האזורים. הטבלה מגדירה נקודות פתיחה של טווחים.
A6: קוד אזור החלוקה: | C6: =IF(B6="","⬜ ממתין לתשובה",IF(B6=33,"✔ נכון — ספרה נחשפה!","✖ לא מדויק, נסו שוב"))
A8: 💡 נתקעתן? גיליון "עזרה" ← תחנה 5
A9: ↩️ חזרה ל"לוח בקרה" כדי לראות אילו ספרות כבר נחשפו.

Sheet תחנה 6
A1: 6️⃣ תחנה 6 — הסכום הסופי
A2: התחנה האחרונה מחברת את הכול. הסכום שהלקוח היה אמור לשלם:
A3: (כמות × מחיר ליחידה) + דמי משלוח
A4: כל שלושת הנתונים כבר בידיכן — שניים מהם מתחנות קודמות. אם המספר לא מסתדר, בדקו קודם את תחנות 2 ו-4.
A6: הסכום הכולל של הזמנה 404 (₪): | C6: =IF(B6="","⬜ ממתין לתשובה",IF(B6=351,"✔ נכון — ספרה נחשפה!","✖ לא מדויק, נסו שוב"))
A8: 💡 נתקעתן? גיליון "עזרה" ← תחנה 6
A9: ↩️ חזרה ל"לוח בקרה" כדי לראות אילו ספרות כבר נחשפו.

Sheet 🔓 פתיחת התיק
A1: 🔓 פתיחת התיק
A2: כשכל שש הספרות נחשפו בלוח הבקרה — הקלידו כאן את הקוד המלא.
A4: הקוד בן שש הספרות:
A6: =IF(B4="","🔒 התיק עדיין נעול. השלימו את שש התחנות, וקחו את הקוד מלוח הבקרה.",IF(B4=402917,"🎉 התיק נפתח!" & CHAR(10) & CHAR(10) & "הזמנה 404: רותם אביב, 6 יחידות רמקול שולחני, 351 ₪ כולל משלוח, לאזור מרכז (קוד 33)." & CHAR(10) & "ההזמנה לא נעלמה — היא מעולם לא נמחקה. המידע היה שם כל הזמן, רק מפוזר על פני חמש טבלאות." & CHAR(10) & CHAR(10) & "וזה בדיוק מה ש-XLOOKUP עושה: לוקחת מידע שמפוזר, ומחזירה אותו לשורה אחת שאפשר לקרוא.","❌ הקוד שגוי. בדקו בלוח הבקרה אילו תחנות עדיין מסומנות ✖."))
A11: 🏆 סיימתן? חזרו ללומדה, ליחידה "תיק 404 — חדר הבריחה", והקלידו שם את הקוד.

Sheet 💡 עזרה
A1: 💡 עזרה ורמזים
A2: קודם נסו לבד. אם עדיין קשה — הרמז העדין כאן נועד לכוון, לא לפתור.
A4: תחנה | B4: רמז עדין | C4: איפה להסתכל
A5: 1 | B5: מה מחפשים = מספר ההזמנה (404). איפה מחפשים = עמודת מספרי ההזמנה. מה מחזירים = עמודת מספרי הלקוח. | C5: טבלה א׳
A6: 2 | B6: שני שלבים: קודם מצאו את המק"ט של הזמנה 404, ואז חפשו את המק"ט הזה בטבלת המוצרים. אפשר להשתמש בתא ביניים. | C6: טבלאות א׳ + ג׳
A7: 3 | B7: עמודת החיפוש היא עמודת מספר הלקוח. עמודת התשובה היא עמודת השם — שנמצאת לפניה. זה לא משנה כלום. | C7: טבלה ב׳
A8: 4 | B8: קודם חשבו את המשקל: כמות × משקל ליחידה. רק אחר כך חפשו במדרגות — עם שני פסיקים ו-1- בסוף. | C8: טבלאות א׳ + ג׳ + ד׳
A9: 5 | B9: המיקוד נמצא בטבלת הלקוחות, לפי מספר הלקוח שמצאתן. ואז חיפוש לא מדויק בטבלת האזורים. | C9: טבלאות ב׳ + ה׳
A10: 6 | B10: זה כבר לא חיפוש — זה חשבון. כמות × מחיר, ועוד דמי משלוח. | C10: התשובות שלכן מתחנות 2 ו-4
A12: 🛠️ תקלות נפוצות
A13: ‎#N/A‎ — לא נמצא. בדקו שהערך שאתן מחפשות באמת קיים בעמודה שסימנתן, ושאין רווח מיותר.
A14: ‎#VALUE!‎ — עמודת החיפוש ועמודת התשובה לא באותו גודל. השוו את מספרי השורות בנוסחה.
A15: ‎#NAME?‎ — גרסת האקסל לא מכירה את XLOOKUP (2019 ומטה). הנוסחה שלכן תקינה; נסו בגוגל שיטס.
A16: תוצאה סבירה אבל שגויה במדרגות — כנראה נכתב 1 במקום ‎-1‎, או שחסר פסיק.
